
FAIL event.intercept() is called multiple times and one of the promises rejects assert_true: expected true got false

