

FAIL event.intercept() throws if used after the dispatch phase assert_throws_dom: function "() => e.intercept()" did not throw

